Workbook

Sheet Cover
A1: Endurance Technologies Ltd (NSE: ENDURANCE)
A2: DCF valuation model, prepared 18 Oct 2026. Student research for learning purposes, not investment advice.
A4: Scenario | B4: =Assumptions!D4 -> Base
A5: Intrinsic value per share | B5: =DCF!B38 -> 1563.5446
A6: Share price (NSE close, 16-Oct-26) | B6: =WACC!B14 -> 2406.4
A7: Upside / (downside) | B7: =DCF!B40 -> -0.35025575
A8: WACC | B8: =WACC!B20 -> 0.11248682
A9: Terminal growth | B9: =Assumptions!$C$28 -> 0.05
A10: Terminal value % of EV | B10: =DCF!B29 -> 0.65522095
A11: Enterprise value (INR Cr) | B11: =DCF!B28 -> 20593.012
A13: How to use
A14: Assumptions!C4 switches scenario: 1 = Bear, 2 = Base, 3 = Bull.
A15: Blue = input (each has a source or rationale beside it). Black = formula. Green = link to another sheet.
A16: Yellow = key outputs and the scenario switch.
A17: Sensitivity tab re-runs the valuation for different WACC, terminal growth and exit multiples.
A18: Historicals: StockAnalysis.com (S&P Global). Company filings on NSE for FY26 and Q1 FY27 results.
A20: Sheets
A21: Assumptions | B21: scenario switch and every forecast driver
A22: DCF | B22: 10-year FCFF forecast, terminal value, equity bridge
A23: Sensitivity | B23: WACC x g, exit multiple, beta x ERP
A24: Comps | B24: listed peer multiples
A25: WACC | B25: cost of capital build-up
A26: Historicals | B26: FY22-FY26 financials and ratios

Sheet Assumptions
A1: Forecast assumptions
A2: Blue cells are inputs. Change the scenario in C4 (1 = Bear, 2 = Base, 3 = Bull) and the whole model updates.
A4: Scenario selected | C4: 2 | D4: =CHOOSE(C4,"Bear","Base","Bull") -> Base
A6: Driver | B6: FY26A | C6: FY27E | D6: FY28E | E6: FY29E | F6: FY30E | G6: FY31E | H6: FY32E | I6: FY33E | J6: FY34E | K6: FY35E | L6: FY36E | M6: Rationale
A7: Revenue growth | M7: Base: Q1 FY27 sales +29.6% (Stoferle, strong 2W/PV volumes); FY27E 17% assumes H2 normalises on a high base. Then fades to 8% by FY36: a 10-year CAGR of ~11%, in line with the company's own 10-year sales CAGR (11%, Screener). Bull adds ABS/alloy-wheel/4W wins; Bear = 2W slowdown + weak Europe.
A8: Bear | C8: 0.12 | D8: 0.09 | E8: 0.09 | F8: 0.08 | G8: 0.08 | H8: 0.07 | I8: 0.07 | J8: 0.06 | K8: 0.06 | L8: 0.06
A9: Base | C9: 0.17 | D9: 0.14 | E9: 0.13 | F9: 0.12 | G9: 0.11 | H9: 0.1 | I9: 0.1 | J9: 0.09 | K9: 0.09 | L9: 0.08
A10: Bull | C10: 0.21 | D10: 0.17 | E10: 0.16 | F10: 0.15 | G10: 0.14 | H10: 0.13 | I10: 0.12 | J10: 0.11 | K10: 0.1 | L10: 0.1
A11: Revenue growth (live) | B11: =Historicals!F22 -> 0.26253373 | C11: =CHOOSE($C$4,C8,C9,C10) -> 0.17 | D11: =CHOOSE($C$4,D8,D9,D10) -> 0.14 | E11: =CHOOSE($C$4,E8,E9,E10) -> 0.13 | F11: =CHOOSE($C$4,F8,F9,F10) -> 0.12 | G11: =CHOOSE($C$4,G8,G9,G10) -> 0.11 | H11: =CHOOSE($C$4,H8,H9,H10) -> 0.1 | I11: =CHOOSE($C$4,I8,I9,I10) -> 0.1 | J11: =CHOOSE($C$4,J8,J9,J10) -> 0.09 | ... L11: =CHOOSE($C$4,L8,L9,L10) -> 0.08
A13: EBITDA margin (excl. other income) | M13: FY26 13.2%, TTM Jun-26 12.9% (input costs). Base recovers to 13.8% from higher-margin ABS, alloy wheels and Europe EV/hybrid programmes. Bear stays ~12.5%.
A14: Bear | C14: 0.124 | D14: 0.124 | E14: 0.125 | F14: 0.125 | G14: 0.125 | H14: 0.125 | I14: 0.125 | J14: 0.125 | K14: 0.125 | L14: 0.125
A15: Base | C15: 0.13 | D15: 0.133 | E15: 0.136 | F15: 0.138 | G15: 0.138 | H15: 0.138 | I15: 0.138 | J15: 0.138 | K15: 0.138 | L15: 0.138
A16: Bull | C16: 0.134 | D16: 0.139 | E16: 0.143 | F16: 0.146 | G16: 0.148 | H16: 0.148 | I16: 0.148 | J16: 0.148 | K16: 0.148 | L16: 0.148
A17: EBITDA margin (live) | B17: =Historicals!F23 -> 0.13230428 | C17: =CHOOSE($C$4,C14,C15,C16) -> 0.13 | D17: =CHOOSE($C$4,D14,D15,D16) -> 0.133 | E17: =CHOOSE($C$4,E14,E15,E16) -> 0.136 | F17: =CHOOSE($C$4,F14,F15,F16) -> 0.138 | G17: =CHOOSE($C$4,G14,G15,G16) -> 0.138 | H17: =CHOOSE($C$4,H14,H15,H16) -> 0.138 | I17: =CHOOSE($C$4,I14,I15,I16) -> 0.138 | J17: =CHOOSE($C$4,J14,J15,J16) -> 0.138 | ... L17: =CHOOSE($C$4,L14,L15,L16) -> 0.138
A20: Other drivers (all scenarios)
A21: D&A % revenue | B21: =Historicals!F24 -> 0.04793812 | C21: 0.047 | D21: 0.047 | E21: 0.047 | F21: 0.047 | G21: 0.047 | H21: 0.047 | I21: 0.047 | J21: 0.047 | K21: 0.047 | L21: 0.047 | M21: FY26 4.8%; held near that as new plants depreciate.
A22: Capex % revenue | B22: =Historicals!F25 -> 0.088778356 | C22: 0.08 | D22: 0.075 | E22: 0.07 | F22: 0.065 | G22: 0.062 | H22: 0.06 | I22: 0.058 | J22: 0.056 | K22: 0.055 | L22: 0.055 | M22: FY26 8.9% (expansion year). Mgmt: FY27 capex similar to FY26. Falls to 5.5% as plants fill; stays above D&A to fund growth.
A23: NWC % revenue | B23: =Historicals!F27 -> 0.070101878 | C23: 0.07 | D23: 0.07 | E23: 0.07 | F23: 0.07 | G23: 0.07 | H23: 0.07 | I23: 0.07 | J23: 0.07 | K23: 0.07 | L23: 0.07 | M23: FY26 7.0% (Rec + Inv - Pay); 5-yr range 7-9%. Held at 7%.
A26: Valuation inputs
A27: Tax rate | C27: 0.2517 | M27: Statutory rate under Sec 115BAA (22% + surcharge + cess).
A28: Terminal growth | C28: 0.05 | M28: Nominal INR; below India's long-run nominal GDP (~10%) — assumes share of growth slows.
A29: Valuation date (base) | B29: 31-Mar-2026 | M29: Cash flows discounted from FY26 year end (mid-year convention).
A30: Days from 31-Mar-26 to 16-Oct-26 | B30: 199 | M30: Equity value is rolled forward at cost of equity to the price date.
A31: FY26 final dividend paid (INR/share) | B31: 11.5 | M31: FY26 press release: ₹11.50/share recommended; paid before price date, so deducted.
A32: Stoferle: price paid for 8% (EUR m) | B32: 6.24 | M32: Q1 FY27 investor presentation: EUR 6.24m for an additional 8% (stake now 68%).
A33: Stoferle: remaining stake to buy | B33: 0.32 | M33: Remaining 32% to be acquired over four years (investor presentation).
A34: EUR/INR | B34: =1146*10/104.3 -> 109.87536 | M34: Implied from Q1 FY27 Europe revenue: ₹1,146 Cr (= ₹11,460m) / EUR 104.3m.
A35: Stoferle future payment (INR Cr) — treated like debt | B35: =B32/0.08*B33*B34/10 -> 274.2489 | M35: Implied value of 100% (6.24/8%) x 32% x FX. EUR m x INR/EUR / 10 = INR crore.

Sheet DCF
A1: Endurance Technologies: discounted cash flow (FCFF)
A2: ="INR crore. Scenario: "&Assumptions!D4&". Mid-year discounting from 31-Mar-2026." -> INR crore. Scenario: Base. Mid-year discounting from 31-Mar-2026.
A4: INR crore | B4: FY26A | C4: FY27E | D4: FY28E | E4: FY29E | F4: FY30E | G4: FY31E | H4: FY32E | I4: FY33E | J4: FY34E | K4: FY35E | L4: FY36E
A5: Revenue | B5: =Historicals!F5 -> 14595.9 | C5: =B5*(1+C6) -> 17077.203 | D5: =C5*(1+D6) -> 19468.011 | E5: =D5*(1+E6) -> 21998.853 | F5: =E5*(1+F6) -> 24638.715 | G5: =F5*(1+G6) -> 27348.974 | H5: =G5*(1+H6) -> 30083.871 | I5: =H5*(1+I6) -> 33092.258 | J5: =I5*(1+J6) -> 36070.562 | ... L5: =K5*(1+L6) -> 42462.265
A6: growth | B6: =Historicals!F22 -> 0.26253373 | C6: =Assumptions!C11 -> 0.17 | D6: =Assumptions!D11 -> 0.14 | E6: =Assumptions!E11 -> 0.13 | F6: =Assumptions!F11 -> 0.12 | G6: =Assumptions!G11 -> 0.11 | H6: =Assumptions!H11 -> 0.1 | I6: =Assumptions!I11 -> 0.1 | J6: =Assumptions!J11 -> 0.09 | ... L6: =Assumptions!L11 -> 0.08
A7: EBITDA | B7: =Historicals!F6 -> 1931.1 | C7: =C5*C8 -> 2220.0364 | D7: =D5*D8 -> 2589.2455 | E7: =E5*E8 -> 2991.844 | F7: =F5*F8 -> 3400.1427 | G7: =G5*G8 -> 3774.1584 | H7: =H5*H8 -> 4151.5742 | I7: =I5*I8 -> 4566.7317 | J7: =J5*J8 -> 4977.7375 | ... L7: =L5*L8 -> 5859.7926
A8: margin | B8: =B7/B5 -> 0.13230428 | C8: =Assumptions!C17 -> 0.13 | D8: =Assumptions!D17 -> 0.133 | E8: =Assumptions!E17 -> 0.136 | F8: =Assumptions!F17 -> 0.138 | G8: =Assumptions!G17 -> 0.138 | H8: =Assumptions!H17 -> 0.138 | I8: =Assumptions!I17 -> 0.138 | J8: =Assumptions!J17 -> 0.138 | ... L8: =Assumptions!L17 -> 0.138
A9: D&A | B9: =Historicals!F7 -> 699.7 | C9: =C5*Assumptions!C21 -> 802.62854 | D9: =D5*Assumptions!D21 -> 914.99654 | E9: =E5*Assumptions!E21 -> 1033.9461 | F9: =F5*Assumptions!F21 -> 1158.0196 | G9: =G5*Assumptions!G21 -> 1285.4018 | H9: =H5*Assumptions!H21 -> 1413.942 | I9: =I5*Assumptions!I21 -> 1555.3361 | J9: =J5*Assumptions!J21 -> 1695.3164 | ... L9: =L5*Assumptions!L21 -> 1995.7265
A10: EBIT | B10: =B7-B9 -> 1231.4 | C10: =C7-C9 -> 1417.4078 | D10: =D7-D9 -> 1674.249 | E10: =E7-E9 -> 1957.8979 | F10: =F7-F9 -> 2242.1231 | G10: =G7-G9 -> 2488.7566 | H10: =H7-H9 -> 2737.6323 | I10: =I7-I9 -> 3011.3955 | ... L10: =L7-L9 -> 3864.0661
A11: Tax on EBIT | C11: =-C10*Assumptions!$C$27 -> -356.76156 | D11: =-D10*Assumptions!$C$27 -> -421.40847 | E11: =-E10*Assumptions!$C$27 -> -492.8029 | F11: =-F10*Assumptions!$C$27 -> -564.34238 | G11: =-G10*Assumptions!$C$27 -> -626.42004 | H11: =-H10*Assumptions!$C$27 -> -689.06205 | I11: =-I10*Assumptions!$C$27 -> -757.96825 | J11: =-J10*Assumptions!$C$27 -> -826.18539 | ... L11: =-L10*Assumptions!$C$27 -> -972.58545
A12: NOPAT | C12: =C10+C11 -> 1060.6463 | D12: =D10+D11 -> 1252.8405 | E12: =E10+E11 -> 1465.095 | F12: =F10+F11 -> 1677.7807 | G12: =G10+G11 -> 1862.3366 | H12: =H10+H11 -> 2048.5702 | I12: =I10+I11 -> 2253.4273 | J12: =J10+J11 -> 2456.2357 | ... L12: =L10+L11 -> 2891.4807
A13: + D&A | C13: =C9 -> 802.62854 | D13: =D9 -> 914.99654 | E13: =E9 -> 1033.9461 | F13: =F9 -> 1158.0196 | G13: =G9 -> 1285.4018 | H13: =H9 -> 1413.942 | I13: =I9 -> 1555.3361 | J13: =J9 -> 1695.3164 | ... L13: =L9 -> 1995.7265
A14: - Capex | B14: =-Historicals!F11 -> -1295.8 | C14: =-C5*Assumptions!C22 -> -1366.1762 | D14: =-D5*Assumptions!D22 -> -1460.1009 | E14: =-E5*Assumptions!E22 -> -1539.9197 | F14: =-F5*Assumptions!F22 -> -1601.5165 | G14: =-G5*Assumptions!G22 -> -1695.6364 | H14: =-H5*Assumptions!H22 -> -1805.0323 | I14: =-I5*Assumptions!I22 -> -1919.351 | J14: =-J5*Assumptions!J22 -> -2019.9515 | ... L14: =-L5*Assumptions!L22 -> -2335.4246
A15: - Increase in NWC | C15: =-(C5-B5)*Assumptions!C23 -> -173.69121 | D15: =-(D5-C5)*Assumptions!D23 -> -167.35659 | E15: =-(E5-D5)*Assumptions!E23 -> -177.1589 | F15: =-(F5-E5)*Assumptions!F23 -> -184.79036 | G15: =-(G5-F5)*Assumptions!G23 -> -189.71811 | H15: =-(H5-G5)*Assumptions!H23 -> -191.44282 | I15: =-(I5-H5)*Assumptions!I23 -> -210.5871 | J15: =-(J5-I5)*Assumptions!J23 -> -208.48123 | ... L15: =-(L5-K5)*Assumptions!L23 -> -220.17471
A16: Free cash flow to firm (FCFF) | C16: =C12+C13+C14+C15 -> 323.40738 | D16: =D12+D13+D14+D15 -> 540.3796 | E16: =E12+E13+E14+E15 -> 781.96248 | F16: =F12+F13+F14+F15 -> 1049.4935 | G16: =G12+G13+G14+G15 -> 1262.3839 | H16: =H12+H13+H14+H15 -> 1466.0371 | I16: =I12+I13+I14+I15 -> 1678.8253 | J16: =J12+J13+J14+J15 -> 1923.1194 | ... L16: =L12+L13+L14+L15 -> 2331.6079
A18: Discount period (years, mid-year) | C18: 0.5 | D18: 1.5 | E18: 2.5 | F18: 3.5 | G18: 4.5 | H18: 5.5 | I18: 6.5 | J18: 7.5 | K18: 8.5 | L18: 9.5
A19: Discount factor | C19: =1/(1+WACC!$B$20)^C18 -> 0.94809654 | D19: =1/(1+WACC!$B$20)^D18 -> 0.85223171 | E19: =1/(1+WACC!$B$20)^E18 -> 0.76606005 | F19: =1/(1+WACC!$B$20)^F18 -> 0.68860146 | G19: =1/(1+WACC!$B$20)^G18 -> 0.61897494 | H19: =1/(1+WACC!$B$20)^H18 -> 0.55638856 | I19: =1/(1+WACC!$B$20)^I18 -> 0.50013047 | J19: =1/(1+WACC!$B$20)^J18 -> 0.44956081 | ... L19: =1/(1+WACC!$B$20)^L18 -> 0.3632442
A20: PV of FCFF | C20: =C16*C19 -> 306.62142 | D20: =D16*D19 -> 460.52863 | E20: =E16*E19 -> 599.03022 | F20: =F16*F19 -> 722.68274 | G20: =G16*G19 -> 781.38398 | H20: =H16*H19 -> 815.68627 | I20: =I16*I19 -> 839.6317 | J20: =J16*J19 -> 864.55913 | ... L20: =L16*L19 -> 846.94304
A22: Valuation
A23: Sum of PV of FCFF (FY27-FY36) | B23: =SUM(C20:L20) -> 7100.039
A24: WACC | B24: =WACC!B20 -> 0.11248682
A25: Terminal growth | B25: =Assumptions!$C$28 -> 0.05
A26: Terminal value (Gordon growth, at FY36) | B26: =L16*(1+B25)/(B24-B25) -> 39179.274
A27: PV of terminal value | B27: =B26/(1+B24)^10 -> 13492.973
A28: Enterprise value (31-Mar-26) | B28: =B23+B27 -> 20593.012
A29: Terminal value % of EV | B29: =B27/B28 -> 0.65522095
A30: + Cash & short-term investments | B30: =Historicals!F16 -> 1889.4
A31: - Total debt incl. leases | B31: =-Historicals!F17 -> -1326.7
A32: - Stoferle remaining stake (minority) | B32: =-Assumptions!B35 -> -274.2489
A33: Equity value (31-Mar-26) | B33: =SUM(B28,B30,B31,B32) -> 20881.463
A34: Roll forward to 16-Oct-26 at cost of equity | B34: =B33*(1+WACC!B10)^(Assumptions!B30/365) -> 22154.955
A35: - FY26 dividend paid | B35: =-Assumptions!B31*WACC!B15 -> -161.76176
A36: Equity value (16-Oct-26) | B36: =B34+B35 -> 21993.193
A37: Shares outstanding (crore) | B37: =WACC!B15 -> 14.06624
A38: Intrinsic value per share (INR) | B38: =B36/B37 -> 1563.5446
A39: Current share price (16-Oct-26) | B39: =WACC!B14 -> 2406.4
A40: Upside / (downside) | B40: =B38/B39-1 -> -0.35025575
A42: Implied multiples at intrinsic value
A43: EV / FY27E EBITDA | B43: =(B36-B30-B31-B32)/C7 -> 9.7767506
A44: Implied terminal EV / EBITDA (FY36) | B44: =B26/L7 -> 6.6861196
...

Sheet Sensitivity
A1: Sensitivity of intrinsic value per share (INR)
A2: Every cell re-runs the valuation with the FCFF stream from the DCF sheet (current scenario).
A4: WACC (down) x terminal growth (across)
B5: 0.04 | C5: 0.045 | D5: 0.05 | E5: 0.055 | F5: 0.06
A6: 0.0975 | B6: =((((SUMPRODUCT(DCF!C16:L16/(1+$A6)^DCF!C18:L18)+DCF!L16*(1+B$5)/($A6-B$5)/(1+$A6)^10))+DCF!$B$30+DCF!$B$31+DCF!$B$32)*(1+WACC!$B$10)^(Assumptions!$B$30/365)+DCF!$B$35)/DCF!$B$37 -> 1843.5174 | C6: =((((SUMPRODUCT(DCF!C16:L16/(1+$A6)^DCF!C18:L18)+DCF!L16*(1+C$5)/($A6-C$5)/(1+$A6)^10))+DCF!$B$30+DCF!$B$31+DCF!$B$32)*(1+WACC!$B$10)^(Assumptions!$B$30/365)+DCF!$B$35)/DCF!$B$37 -> 1969.61 | D6: =((((SUMPRODUCT(DCF!C16:L16/(1+$A6)^DCF!C18:L18)+DCF!L16*(1+D$5)/($A6-D$5)/(1+$A6)^10))+DCF!$B$30+DCF!$B$31+DCF!$B$32)*(1+WACC!$B$10)^(Assumptions!$B$30/365)+DCF!$B$35)/DCF!$B$37 -> 2122.2484 | E6: =((((SUMPRODUCT(DCF!C16:L16/(1+$A6)^DCF!C18:L18)+DCF!L16*(1+E$5)/($A6-E$5)/(1+$A6)^10))+DCF!$B$30+DCF!$B$31+DCF!$B$32)*(1+WACC!$B$10)^(Assumptions!$B$30/365)+DCF!$B$35)/DCF!$B$37 -> 2310.8017 | F6: =((((SUMPRODUCT(DCF!C16:L16/(1+$A6)^DCF!C18:L18)+DCF!L16*(1+F$5)/($A6-F$5)/(1+$A6)^10))+DCF!$B$30+DCF!$B$31+DCF!$B$32)*(1+WACC!$B$10)^(Assumptions!$B$30/365)+DCF!$B$35)/DCF!$B$37 -> 2549.6359
A7: 0.1025 | B7: =((((SUMPRODUCT(DCF!C16:L16/(1+$A7)^DCF!C18:L18)+DCF!L16*(1+B$5)/($A7-B$5)/(1+$A7)^10))+DCF!$B$30+DCF!$B$31+DCF!$B$32)*(1+WACC!$B$10)^(Assumptions!$B$30/365)+DCF!$B$35)/DCF!$B$37 -> 1676.9558 | C7: =((((SUMPRODUCT(DCF!C16:L16/(1+$A7)^DCF!C18:L18)+DCF!L16*(1+C$5)/($A7-C$5)/(1+$A7)^10))+DCF!$B$30+DCF!$B$31+DCF!$B$32)*(1+WACC!$B$10)^(Assumptions!$B$30/365)+DCF!$B$35)/DCF!$B$37 -> 1778.628 | D7: =((((SUMPRODUCT(DCF!C16:L16/(1+$A7)^DCF!C18:L18)+DCF!L16*(1+D$5)/($A7-D$5)/(1+$A7)^10))+DCF!$B$30+DCF!$B$31+DCF!$B$32)*(1+WACC!$B$10)^(Assumptions!$B$30/365)+DCF!$B$35)/DCF!$B$37 -> 1899.6663 | E7: =((((SUMPRODUCT(DCF!C16:L16/(1+$A7)^DCF!C18:L18)+DCF!L16*(1+E$5)/($A7-E$5)/(1+$A7)^10))+DCF!$B$30+DCF!$B$31+DCF!$B$32)*(1+WACC!$B$10)^(Assumptions!$B$30/365)+DCF!$B$35)/DCF!$B$37 -> 2046.1864 | F7: =((((SUMPRODUCT(DCF!C16:L16/(1+$A7)^DCF!C18:L18)+DCF!L16*(1+F$5)/($A7-F$5)/(1+$A7)^10))+DCF!$B$30+DCF!$B$31+DCF!$B$32)*(1+WACC!$B$10)^(Assumptions!$B$30/365)+DCF!$B$35)/DCF!$B$37 -> 2227.1818
A8: 0.1075 | B8: =((((SUMPRODUCT(DCF!C16:L16/(1+$A8)^DCF!C18:L18)+DCF!L16*(1+B$5)/($A8-B$5)/(1+$A8)^10))+DCF!$B$30+DCF!$B$31+DCF!$B$32)*(1+WACC!$B$10)^(Assumptions!$B$30/365)+DCF!$B$35)/DCF!$B$37 -> 1535.7001 | C8: =((((SUMPRODUCT(DCF!C16:L16/(1+$A8)^DCF!C18:L18)+DCF!L16*(1+C$5)/($A8-C$5)/(1+$A8)^10))+DCF!$B$30+DCF!$B$31+DCF!$B$32)*(1+WACC!$B$10)^(Assumptions!$B$30/365)+DCF!$B$35)/DCF!$B$37 -> 1618.8535 | D8: =((((SUMPRODUCT(DCF!C16:L16/(1+$A8)^DCF!C18:L18)+DCF!L16*(1+D$5)/($A8-D$5)/(1+$A8)^10))+DCF!$B$30+DCF!$B$31+DCF!$B$32)*(1+WACC!$B$10)^(Assumptions!$B$30/365)+DCF!$B$35)/DCF!$B$37 -> 1716.4684 | E8: =((((SUMPRODUCT(DCF!C16:L16/(1+$A8)^DCF!C18:L18)+DCF!L16*(1+E$5)/($A8-E$5)/(1+$A8)^10))+DCF!$B$30+DCF!$B$31+DCF!$B$32)*(1+WACC!$B$10)^(Assumptions!$B$30/365)+DCF!$B$35)/DCF!$B$37 -> 1832.6765 | F8: =((((SUMPRODUCT(DCF!C16:L16/(1+$A8)^DCF!C18:L18)+DCF!L16*(1+F$5)/($A8-F$5)/(1+$A8)^10))+DCF!$B$30+DCF!$B$31+DCF!$B$32)*(1+WACC!$B$10)^(Assumptions!$B$30/365)+DCF!$B$35)/DCF!$B$37 -> 1973.3496
A9: 0.1125 | B9: =((((SUMPRODUCT(DCF!C16:L16/(1+$A9)^DCF!C18:L18)+DCF!L16*(1+B$5)/($A9-B$5)/(1+$A9)^10))+DCF!$B$30+DCF!$B$31+DCF!$B$32)*(1+WACC!$B$10)^(Assumptions!$B$30/365)+DCF!$B$35)/DCF!$B$37 -> 1414.4878 | C9: =((((SUMPRODUCT(DCF!C16:L16/(1+$A9)^DCF!C18:L18)+DCF!L16*(1+C$5)/($A9-C$5)/(1+$A9)^10))+DCF!$B$30+DCF!$B$31+DCF!$B$32)*(1+WACC!$B$10)^(Assumptions!$B$30/365)+DCF!$B$35)/DCF!$B$37 -> 1483.3237 | D9: =((((SUMPRODUCT(DCF!C16:L16/(1+$A9)^DCF!C18:L18)+DCF!L16*(1+D$5)/($A9-D$5)/(1+$A9)^10))+DCF!$B$30+DCF!$B$31+DCF!$B$32)*(1+WACC!$B$10)^(Assumptions!$B$30/365)+DCF!$B$35)/DCF!$B$37 -> 1563.1735 | E9: =((((SUMPRODUCT(DCF!C16:L16/(1+$A9)^DCF!C18:L18)+DCF!L16*(1+E$5)/($A9-E$5)/(1+$A9)^10))+DCF!$B$30+DCF!$B$31+DCF!$B$32)*(1+WACC!$B$10)^(Assumptions!$B$30/365)+DCF!$B$35)/DCF!$B$37 -> 1656.9101 | F9: =((((SUMPRODUCT(DCF!C16:L16/(1+$A9)^DCF!C18:L18)+DCF!L16*(1+F$5)/($A9-F$5)/(1+$A9)^10))+DCF!$B$30+DCF!$B$31+DCF!$B$32)*(1+WACC!$B$10)^(Assumptions!$B$30/365)+DCF!$B$35)/DCF!$B$37 -> 1768.5014
A10: 0.1175 | B10: =((((SUMPRODUCT(DCF!C16:L16/(1+$A10)^DCF!C18:L18)+DCF!L16*(1+B$5)/($A10-B$5)/(1+$A10)^10))+DCF!$B$30+DCF!$B$31+DCF!$B$32)*(1+WACC!$B$10)^(Assumptions!$B$30/365)+DCF!$B$35)/DCF!$B$37 -> 1309.4156 | C10: =((((SUMPRODUCT(DCF!C16:L16/(1+$A10)^DCF!C18:L18)+DCF!L16*(1+C$5)/($A10-C$5)/(1+$A10)^10))+DCF!$B$30+DCF!$B$31+DCF!$B$32)*(1+WACC!$B$10)^(Assumptions!$B$30/365)+DCF!$B$35)/DCF!$B$37 -> 1366.9981 | D10: =((((SUMPRODUCT(DCF!C16:L16/(1+$A10)^DCF!C18:L18)+DCF!L16*(1+D$5)/($A10-D$5)/(1+$A10)^10))+DCF!$B$30+DCF!$B$31+DCF!$B$32)*(1+WACC!$B$10)^(Assumptions!$B$30/365)+DCF!$B$35)/DCF!$B$37 -> 1433.1112 | E10: =((((SUMPRODUCT(DCF!C16:L16/(1+$A10)^DCF!C18:L18)+DCF!L16*(1+E$5)/($A10-E$5)/(1+$A10)^10))+DCF!$B$30+DCF!$B$31+DCF!$B$32)*(1+WACC!$B$10)^(Assumptions!$B$30/365)+DCF!$B$35)/DCF!$B$37 -> 1509.8025 | F10: =((((SUMPRODUCT(DCF!C16:L16/(1+$A10)^DCF!C18:L18)+DCF!L16*(1+F$5)/($A10-F$5)/(1+$A10)^10))+DCF!$B$30+DCF!$B$31+DCF!$B$32)*(1+WACC!$B$10)^(Assumptions!$B$30/365)+DCF!$B$35)/DCF!$B$37 -> 1599.8313
A11: 0.1225 | B11: =((((SUMPRODUCT(DCF!C16:L16/(1+$A11)^DCF!C18:L18)+DCF!L16*(1+B$5)/($A11-B$5)/(1+$A11)^10))+DCF!$B$30+DCF!$B$31+DCF!$B$32)*(1+WACC!$B$10)^(Assumptions!$B$30/365)+DCF!$B$35)/DCF!$B$37 -> 1217.528 | C11: =((((SUMPRODUCT(DCF!C16:L16/(1+$A11)^DCF!C18:L18)+DCF!L16*(1+C$5)/($A11-C$5)/(1+$A11)^10))+DCF!$B$30+DCF!$B$31+DCF!$B$32)*(1+WACC!$B$10)^(Assumptions!$B$30/365)+DCF!$B$35)/DCF!$B$37 -> 1266.1379 | D11: =((((SUMPRODUCT(DCF!C16:L16/(1+$A11)^DCF!C18:L18)+DCF!L16*(1+D$5)/($A11-D$5)/(1+$A11)^10))+DCF!$B$30+DCF!$B$31+DCF!$B$32)*(1+WACC!$B$10)^(Assumptions!$B$30/365)+DCF!$B$35)/DCF!$B$37 -> 1321.4526 | E11: =((((SUMPRODUCT(DCF!C16:L16/(1+$A11)^DCF!C18:L18)+DCF!L16*(1+E$5)/($A11-E$5)/(1+$A11)^10))+DCF!$B$30+DCF!$B$31+DCF!$B$32)*(1+WACC!$B$10)^(Assumptions!$B$30/365)+DCF!$B$35)/DCF!$B$37 -> 1384.9621 | F11: =((((SUMPRODUCT(DCF!C16:L16/(1+$A11)^DCF!C18:L18)+DCF!L16*(1+F$5)/($A11-F$5)/(1+$A11)^10))+DCF!$B$30+DCF!$B$31+DCF!$B$32)*(1+WACC!$B$10)^(Assumptions!$B$30/365)+DCF!$B$35)/DCF!$B$37 -> 1458.6331
A12: 0.1275 | B12: =((((SUMPRODUCT(DCF!C16:L16/(1+$A12)^DCF!C18:L18)+DCF!L16*(1+B$5)/($A12-B$5)/(1+$A12)^10))+DCF!$B$30+DCF!$B$31+DCF!$B$32)*(1+WACC!$B$10)^(Assumptions!$B$30/365)+DCF!$B$35)/DCF!$B$37 -> 1136.5458 | C12: =((((SUMPRODUCT(DCF!C16:L16/(1+$A12)^DCF!C18:L18)+DCF!L16*(1+C$5)/($A12-C$5)/(1+$A12)^10))+DCF!$B$30+DCF!$B$31+DCF!$B$32)*(1+WACC!$B$10)^(Assumptions!$B$30/365)+DCF!$B$35)/DCF!$B$37 -> 1177.9121 | D12: =((((SUMPRODUCT(DCF!C16:L16/(1+$A12)^DCF!C18:L18)+DCF!L16*(1+D$5)/($A12-D$5)/(1+$A12)^10))+DCF!$B$30+DCF!$B$31+DCF!$B$32)*(1+WACC!$B$10)^(Assumptions!$B$30/365)+DCF!$B$35)/DCF!$B$37 -> 1224.616 | E12: =((((SUMPRODUCT(DCF!C16:L16/(1+$A12)^DCF!C18:L18)+DCF!L16*(1+E$5)/($A12-E$5)/(1+$A12)^10))+DCF!$B$30+DCF!$B$31+DCF!$B$32)*(1+WACC!$B$10)^(Assumptions!$B$30/365)+DCF!$B$35)/DCF!$B$37 -> 1277.7618 | F12: =((((SUMPRODUCT(DCF!C16:L16/(1+$A12)^DCF!C18:L18)+DCF!L16*(1+F$5)/($A12-F$5)/(1+$A12)^10))+DCF!$B$30+DCF!$B$31+DCF!$B$32)*(1+WACC!$B$10)^(Assumptions!$B$30/365)+DCF!$B$35)/DCF!$B$37 -> 1338.781
A14: Current price | B14: =WACC!B14 -> 2406.4
A15: Live WACC in model | B15: =WACC!B20 -> 0.11248682
A17: Cross-check: exit multiple instead of Gordon growth
A18: Terminal EV / FY36 EBITDA | B18: 10 | C18: 12 | D18: 14 | E18: 16 | F18: 18
A19: Value per share (INR) | B19: =(((SUMPRODUCT(DCF!C16:L16/(1+WACC!$B$20)^DCF!C18:L18)+B$18*DCF!$L$7/(1+WACC!$B$20)^10)+DCF!$B$30+DCF!$B$31+DCF!$B$32)*(1+WACC!$B$10)^(Assumptions!$B$30/365)+DCF!$B$35)/DCF!$B$37 -> 2067.9761 | C19: =(((SUMPRODUCT(DCF!C16:L16/(1+WACC!$B$20)^DCF!C18:L18)+C$18*DCF!$L$7/(1+WACC!$B$20)^10)+DCF!$B$30+DCF!$B$31+DCF!$B$32)*(1+WACC!$B$10)^(Assumptions!$B$30/365)+DCF!$B$35)/DCF!$B$37 -> 2372.4117 | D19: =(((SUMPRODUCT(DCF!C16:L16/(1+WACC!$B$20)^DCF!C18:L18)+D$18*DCF!$L$7/(1+WACC!$B$20)^10)+DCF!$B$30+DCF!$B$31+DCF!$B$32)*(1+WACC!$B$10)^(Assumptions!$B$30/365)+DCF!$B$35)/DCF!$B$37 -> 2676.8473 | E19: =(((SUMPRODUCT(DCF!C16:L16/(1+WACC!$B$20)^DCF!C18:L18)+E$18*DCF!$L$7/(1+WACC!$B$20)^10)+DCF!$B$30+DCF!$B$31+DCF!$B$32)*(1+WACC!$B$10)^(Assumptions!$B$30/365)+DCF!$B$35)/DCF!$B$37 -> 2981.2829 | F19: =(((SUMPRODUCT(DCF!C16:L16/(1+WACC!$B$20)^DCF!C18:L18)+F$18*DCF!$L$7/(1+WACC!$B$20)^10)+DCF!$B$30+DCF!$B$31+DCF!$B$32)*(1+WACC!$B$10)^(Assumptions!$B$30/365)+DCF!$B$35)/DCF!$B$37 -> 3285.7185
A20: Implied terminal growth | B20: =(B$18*DCF!$L$7*WACC!$B$20-DCF!L16)/(B$18*DCF!$L$7+DCF!L16) -> 0.069914969 | C20: =(C$18*DCF!$L$7*WACC!$B$20-DCF!L16)/(C$18*DCF!$L$7+DCF!L16) -> 0.07678256 | D20: =(D$18*DCF!$L$7*WACC!$B$20-DCF!L16)/(D$18*DCF!$L$7+DCF!L16) -> 0.081742209 | E20: =(E$18*DCF!$L$7*WACC!$B$20-DCF!L16)/(E$18*DCF!$L$7+DCF!L16) -> 0.085492032 | F20: =(F$18*DCF!$L$7*WACC!$B$20-DCF!L16)/(F$18*DCF!$L$7+DCF!L16) -> 0.088426583
A22: Beta (down) x equity risk premium (across): WACC
B23: 0.06 | C23: 0.0708 | D23: 0.08
A24: 0.7 | B24: =WACC!$B$18*(WACC!$B$7+$A24*B$23)+WACC!$B$19*WACC!$B$13 -> 0.09362991 | C24: =WACC!$B$18*(WACC!$B$7+$A24*C$23)+WACC!$B$19*WACC!$B$13 -> 0.10090477 | D24: =WACC!$B$18*(WACC!$B$7+$A24*D$23)+WACC!$B$19*WACC!$B$13 -> 0.10710188
A25: 0.87 | B25: =WACC!$B$18*(WACC!$B$7+$A25*B$23)+WACC!$B$19*WACC!$B$13 -> 0.1034452 | C25: =WACC!$B$18*(WACC!$B$7+$A25*C$23)+WACC!$B$19*WACC!$B$13 -> 0.11248682 | D25: =WACC!$B$18*(WACC!$B$7+$A25*D$23)+WACC!$B$19*WACC!$B$13 -> 0.12018894
A26: 1 | B26: =WACC!$B$18*(WACC!$B$7+$A26*B$23)+WACC!$B$19*WACC!$B$13 -> 0.11095102 | C26: =WACC!$B$18*(WACC!$B$7+$A26*C$23)+WACC!$B$19*WACC!$B$13 -> 0.12134368 | D26: =WACC!$B$18*(WACC!$B$7+$A26*D$23)+WACC!$B$19*WACC!$B$13 -> 0.13019669
A27: 1.2 | B27: =WACC!$B$18*(WACC!$B$7+$A27*B$23)+WACC!$B$19*WACC!$B$13 -> 0.12249842 | C27: =WACC!$B$18*(WACC!$B$7+$A27*C$23)+WACC!$B$19*WACC!$B$13 -> 0.13496961 | D27: =WACC!$B$18*(WACC!$B$7+$A27*D$23)+WACC!$B$19*WACC!$B$13 -> 0.14559323

Sheet Comps
A1: Listed Indian auto-component peers
A2: Market data as reported by Value Research / 5paisa on the date shown (INR). Blue = sourced input.
A4: Company | B4: Price | C4: Mkt cap (Cr) | D4: P/E (TTM) | E4: EV/EBITDA | F4: ROE | G4: As of | H4: Note
A5: Endurance Technologies | B5: 2406.4 | C5: 33829 | D5: 34.9 | E5: 15.6 | F5: 0.149 | G5: 16-Oct-26 | H5: Value Research; ROE from Screener
A6: Uno Minda | B6: 1108 | C6: 64110 | D6: 53.3 | E6: 28.7 | F6: 0.205 | G6: 16-Oct-26 | H6: Lighting, switches, alloy wheels, EV parts
A7: Sona BLW Precision | B7: 800 | C7: 49859 | D7: 71.6 | E7: 38.7 | F7: 0.111 | G7: 16-Oct-26 | H7: EV driveline; premium for EV exposure
A8: Gabriel India | B8: 1303.6 | C8: 25075 | D8: 84.2 | E8: 51.6 | F8: 0.198 | G8: 05-Oct-26 | H8: Closest product peer (suspension)
A9: Minda Corporation | B9: 649.85 | C9: 15537 | D9: 31 | E9: n/a | F9: n/a | G9: 16-Oct-26 | H9: 5paisa; EV/EBITDA, ROE not shown
A10: Bharat Forge | B10: 1833 | C10: 89129 | D10: 126.2 | E10: 30 | F10: 0.116 | G10: 05-Oct-26 | H10: Forgings + defence; P/E distorted, excluded from median
A12: Peer median (excl. Endurance, Bharat Forge) | D12: =MEDIAN(D6:D9) -> 62.45 | E12: =MEDIAN(E6:E8) -> 38.7 | F12: =MEDIAN(F6:F8) -> 0.198
A13: Endurance discount to peer median | D13: =D5/D12-1 -> -0.44115292 | E13: =E5/E12-1 -> -0.59689922
A15: Implied value per share at peer median P/E x Endurance TTM EPS (₹68.95, StockAnalysis TTM Jun-26) | D15: =D12*68.95 -> 4305.9275
A16: Implied value at Endurance's own TTM P/E applied to FY27E EPS proxy is in the pitch deck.
A18: Sources: valueresearchonline.com stock pages (Uno Minda, Sona BLW, Gabriel India, Bharat Forge, Endurance key ratios); 5paisa.com (Minda Corp); screener.in (Endurance ROE). Retrieved 18 Oct 2026.

Sheet Historicals
A1: Endurance Technologies: consolidated historicals
A2: INR crore, fiscal years ending 31 March. Blue = reported figures (source in column G).
A4: INR crore | B4: FY22 | C4: FY23 | D4: FY24 | E4: FY25 | F4: FY26 | G4: Source
A5: Revenue | B5: 7549.1 | C5: 8804 | D5: 10240.9 | E5: 11560.8 | F5: 14595.9 | G5: StockAnalysis.com income statement (S&P Global data), stockanalysis.com/quote/nse/ENDURANCE/financials/income-statement/
A6: EBITDA | B6: 941.4 | C6: 1018.9 | D6: 1307.1 | E6: 1531.7 | F6: 1931.1 | G6: StockAnalysis.com income statement (S&P Global data), stockanalysis.com/quote/nse/ENDURANCE/financials/income-statement/
A7: D&A | B7: 358.5 | C7: 404.2 | D7: 453.1 | E7: 519.3 | F7: 699.7 | G7: StockAnalysis.com income statement (S&P Global data), stockanalysis.com/quote/nse/ENDURANCE/financials/income-statement/
A8: EBIT | B8: 582.9 | C8: 614.7 | D8: 854 | E8: 1012.4 | F8: 1231.4 | G8: StockAnalysis.com income statement (S&P Global data), stockanalysis.com/quote/nse/ENDURANCE/financials/income-statement/
A9: Net income | B9: 460.7 | C9: 479.6 | D9: 680.5 | E9: 836.4 | F9: 951.7 | G9: StockAnalysis.com income statement (S&P Global data), stockanalysis.com/quote/nse/ENDURANCE/financials/income-statement/
A10: Operating cash flow | B10: 741.6 | C10: 862 | D10: 1057.1 | E10: 1531.7 | F10: 1850.7 | G10: StockAnalysis.com cash flow, stockanalysis.com/quote/nse/ENDURANCE/financials/cash-flow-statement/
A11: Capex | B11: 529 | C11: 636.3 | D11: 834.8 | E11: 1053.4 | F11: 1295.8 | G11: StockAnalysis.com cash flow, stockanalysis.com/quote/nse/ENDURANCE/financials/cash-flow-statement/
A12: Acquisitions | B12: 5.9 | C12: 120.6 | D12: 6.9 | E12: 20.3 | F12: 357.6 | G12: StockAnalysis.com cash flow, stockanalysis.com/quote/nse/ENDURANCE/financials/cash-flow-statement/
A13: Receivables | B13: 1136.7 | C13: 1347.7 | D13: 1519.7 | E13: 1693.3 | F13: 2145.3 | G13: StockAnalysis.com balance sheet, stockanalysis.com/quote/nse/ENDURANCE/financials/balance-sheet/
A14: Inventory | B14: 728.7 | C14: 865.3 | D14: 915.3 | E14: 984.4 | F14: 1247.2 | G14: StockAnalysis.com balance sheet, stockanalysis.com/quote/nse/ENDURANCE/financials/balance-sheet/
A15: Payables | B15: 1241.3 | C15: 1425.7 | D15: 1604.5 | E15: 1795 | F15: 2369.3 | G15: StockAnalysis.com balance sheet, stockanalysis.com/quote/nse/ENDURANCE/financials/balance-sheet/
A16: Cash & ST investments | B16: 888.2 | C16: 934 | D16: 1269.7 | E16: 1806.8 | F16: 1889.4 | G16: StockAnalysis.com balance sheet, stockanalysis.com/quote/nse/ENDURANCE/financials/balance-sheet/
... A19: EPS (INR) | B19: 32.75 | C19: 34.09 | D19: 48.38 | E19: 59.46 | F19: 67.66 | G19: StockAnalysis.com income statement (S&P Global data), stockanalysis.com/quote/nse/ENDURANCE/financials/income-statement/
A21: Ratios (formulas)
A22: Revenue growth | C22: =IF(B5=0,0,C5/B5-1) -> 0.16623174 | D22: =IF(C5=0,0,D5/C5-1) -> 0.1632099 | E22: =IF(D5=0,0,E5/D5-1) -> 0.12888516 | F22: =IF(E5=0,0,F5/E5-1) -> 0.26253373
A23: EBITDA margin | B23: =B6/B5 -> 0.12470361 | C23: =C6/C5 -> 0.11573149 | D23: =D6/D5 -> 0.12763527 | E23: =E6/E5 -> 0.13249083 | F23: =F6/F5 -> 0.13230428
A24: D&A % revenue | B24: =B7/B5 -> 0.047489105 | C24: =C7/C5 -> 0.04591095 | D24: =D7/D5 -> 0.044244158 | E24: =E7/E5 -> 0.044919037 | F24: =F7/F5 -> 0.04793812
A25: Capex % revenue | B25: =B11/B5 -> 0.070074578 | C25: =C11/C5 -> 0.072273966 | D25: =D11/D5 -> 0.081516273 | E25: =E11/E5 -> 0.091118262 | F25: =F11/F5 -> 0.088778356
A26: Net working capital (Rec + Inv - Pay) | B26: =B13+B14-B15 -> 624.1 | C26: =C13+C14-C15 -> 787.3 | D26: =D13+D14-D15 -> 830.5 | E26: =E13+E14-E15 -> 882.7 | F26: =F13+F14-F15 -> 1023.2
A27: NWC % revenue | B27: =B26/B5 -> 0.082672107 | C27: =C26/C5 -> 0.089425261 | D27: =D26/D5 -> 0.081096388 | E27: =E26/E5 -> 0.076352848 | F27: =F26/F5 -> 0.070101878
A28: Effective tax proxy: 1 - NI/EBIT | B28: =1-B9/B8 -> 0.20964145 | C28: =1-C9/C8 -> 0.21978201 | D28: =1-D9/D8 -> 0.20316159 | E28: =1-E9/E8 -> 0.17384433 | F28: =1-F9/F8 -> 0.22713984
A29: ROE (NI / closing equity) | B29: =B9/B18 -> 0.11752551 | C29: =C9/C18 -> 0.10870107 | D29: =D9/D18 -> 0.13671797 | E29: =E9/E18 -> 0.14629027 | F29: =F9/F18 -> 0.13912116
A30: Free cash flow (OCF - capex) | B30: =B10-B11 -> 212.6 | C30: =C10-C11 -> 225.7 | D30: =D10-D11 -> 222.3 | E30: =E10-E11 -> 478.3 | F30: =F10-F11 -> 554.9
A31: Net cash / (debt) | B31: =B16-B17 -> 458.6 | C31: =C16-C17 -> 419.2 | D31: =D16-D17 -> 504.4 | E31: =E16-E17 -> 863.1 | F31: =F16-F17 -> 562.7
A33: Note: EBITDA here excludes other income (S&P definition). Company-reported FY26 EBITDA including other income was ₹2,090 Cr (14.2% of total income), per the FY26 press release (NSE filing, 14 May 2026).
A34: Note: 'NI / EBIT' mixes interest, other income and tax, so it is only a sanity check; the model uses the statutory 25.17% rate (Section 115BAA).

Sheet WACC
A1: Discount rate (WACC)
A2: INR, nominal. Blue = input with source; black = formula.
A4: Item | B4: Value | C4: Source / reasoning
A5: India 10Y G-sec yield | B5: 0.0718 | C5: Trading Economics, 28 Sep 2026: India 10Y near a two-year high at ~7.18%.
A6: India sovereign default spread | B6: 0.0187 | C6: Damodaran country risk table (updated 5 Jan 2026): India Baa3, adjusted default spread 1.87%.
A7: INR risk-free rate | B7: =B5-B6 -> 0.0531 | C7: Govt yield less default spread, so country risk isn't counted twice (it is already in the ERP below).
A8: Levered beta | B8: 0.87 | C8: sharpely.in (price date 16 Oct 2026). Below 1: auto parts are cyclical, but ENDU is net cash. Flexed in Sensitivity.
A9: Equity risk premium (India, total) | B9: 0.0708 | C9: Damodaran (5 Jan 2026): mature-market ERP 4.23% + India CRP 2.85%.
A10: Cost of equity (CAPM) | B10: =B7+B8*B9 -> 0.114696 | C10: Rf + beta x ERP
A11: Pre-tax cost of debt | B11: 0.075 | C11: Assumption. FY26 interest / avg debt is ~5% (cheap Euro loans + leases); 7.5% reflects marginal INR borrowing for an AA+ issuer (ICRA AA+ Stable, Sep 2025).
A12: Tax rate | B12: =Assumptions!C27 -> 0.2517 | C12: Linked to Assumptions
A13: After-tax cost of debt | B13: =B11*(1-B12) -> 0.0561225
A14: Share price (INR) | B14: 2406.4 | C14: NSE close 16 Oct 2026 (Dhan / 5paisa / Value Research).
A15: Shares outstanding (crore) | B15: =B16/B14 -> 14.06624 | C15: Implied from market cap / price.
A16: Market cap (INR Cr) | B16: 33849 | C16: Dhan / 5paisa, 16 Oct 2026: ₹33,849 Cr.
A17: Total debt incl. leases (INR Cr) | B17: =Historicals!F17 -> 1326.7 | C17: FY26 balance sheet
A18: Equity weight | B18: =B16/(B16+B17) -> 0.96228362 | C18: Market values
A19: Debt weight | B19: =B17/(B16+B17) -> 0.037716378
A20: WACC | B20: =B18*B10+B19*B13 -> 0.11248682
